<html><head><title>AI DAG Log Analysis Report</title>
    <style>
    body { font-family: Arial, sans-serif; padding: 20px; background: #f4f7f6; color: #333; }
    h1, h2, h3 { color: #2c3e50; }
    .summary-section { background: #e8f5e9; border-left: 5px solid #4CAF50; padding: 15px; margin-bottom: 30px; border-radius: 8px; box-shadow: 0 2px 4px rgba(0,0,0,0.1); }
    .error-card { background: #fff; border: 1px solid #ddd; border-radius: 8px; padding: 20px; margin-bottom: 20px; box-shadow: 0 2px 5px rgba(0,0,0,0.05); }
    .error-card.severity-HIGH { border-left: 5px solid #e74c3c; } /* Red */
    .error-card.severity-MEDIUM { border-left: 5px solid #f39c12; } /* Orange */
    .error-card.severity-LOW { border-left: 5px solid #2ecc71; } /* Green */
    pre { background: #ecf0f1; padding: 10px; border-radius: 5px; overflow-x: auto; white-space: pre-wrap; word-wrap: break-word; font-family: 'Courier New', monospace; font-size: 0.9em; }
    .meta-data { font-size: 0.9em; color: #666; margin-bottom: 10px; }
    .section-title { font-weight: bold; margin-top: 15px; margin-bottom: 5px; color: #34495e; }
    ul { list-style-type: disc; margin-left: 20px; }
    </style></head><body>
    <h1>ðŸ§  AI DAG Log Analysis Report</h1>

    <div class="summary-section">
        <h2>Executive Summary</h2>
        <pre>{}</pre>
    </div>

    <h2>Detailed Error Analysis (6 Errors)</h2>
    
        <div class="error-card severity-HIGH">
            <h3>ðŸš¨ Database Connection in Challenge_contest_from_Postgres_to_Snowflake.scheduled__2025-07-20T03_10_00+00_00</h3>
            <div class="meta-data">
                <strong>Severity:</strong> HIGH | 
                <strong>File:</strong> attempt=3.log | 
                <strong>Execution:</strong> task_id=load_contest_winners_operator
            </div>
            
            <div class="section-title">Error Details:</div>
            <pre>Line 1: [2025-07-21T03:20:50.217+0000] {{taskinstance.py:1824}} ERROR - Task failed with exception</pre>
            
            <div class="section-title">Context Lines:</div>
            <pre>[2025-07-21T03:20:50.217+0000] {{taskinstance.py:1824}} ERROR - Task failed with exception
Traceback (most recent call last):
  File &quot;/usr/local/airflow/.local/lib/python3.10/site-packages/sqlalchemy/engine/base.py&quot;, line 1910, in _execute_context</pre>
            
            <div class="section-title">AI Analysis & Suggestions:</div>
            <pre>**Root Cause:** Failed to establish a connection with Snowflake database, indicating a potential issue with the database credentials or configuration.

**Recommended Solution:**
  - Verify that the Snowflake database credentials are correct and up-to-date in the Airflow settings.
  - Check the Snowflake database connection string for any typos or formatting errors.
  - Ensure that the Airflow user has the necessary permissions to access the Snowflake database.

**Prevention Tips:**
  - Regularly review and update Airflow database credentials to prevent stale connections.
  - Implement logging mechanisms to track database connection attempts and failures.
  - Use environment variables or secure storage to store sensitive database credentials.</pre>
            
            
        </div>
        
        <div class="error-card severity-MEDIUM">
            <h3>ðŸš¨ Database Connection in Challenge_contest_from_Postgres_to_Snowflake.scheduled__2025-07-20T03_10_00+00_00</h3>
            <div class="meta-data">
                <strong>Severity:</strong> MEDIUM | 
                <strong>File:</strong> attempt=1.log | 
                <strong>Execution:</strong> task_id=load_contest_winners_operator
            </div>
            
            <div class="section-title">Error Details:</div>
            <pre>Line 1: [2025-07-21T03:10:36.600+0000] {{standard_task_runner.py:104}} ERROR - Failed to execute job 445840 for task load_contest_winners_operator ((psycopg2.errors.UndefinedTable) relation &quot;contest_winners&quot; does not exist</pre>
            
            <div class="section-title">Context Lines:</div>
            <pre>[2025-07-21T03:10:36.600+0000] {{standard_task_runner.py:104}} ERROR - Failed to execute job 445840 for task load_contest_winners_operator ((psycopg2.errors.UndefinedTable) relation &quot;contest_winners&quot; does not exist
LINE 2:         from contest_winners
                     ^</pre>
            
            <div class="section-title">AI Analysis & Suggestions:</div>
            <pre>**Root Cause:** The &#x27;contest_winners&#x27; table does not exist in the PostgreSQL database, causing a failure in the load_contest_winners_operator task.

**Recommended Solution:**
  - Check the PostgreSQL database schema to ensure the &#x27;contest_winners&#x27; table exists and is correctly spelled.
  - Verify that the table was created with the correct name and structure before running the DAG.
  - Update the DAG&#x27;s SQL query or connection string to reference the correct table name.

**Prevention Tips:**
  - Regularly review database schema changes to ensure data integrity.
  - Use Airflow&#x27;s built-in support for dynamic table names or parameterized queries.
  - Implement automated testing of DAGs against different database schemas.</pre>
            
            
        </div>
        
        <div class="error-card severity-HIGH">
            <h3>ðŸš¨ Database Connection in Challenge_contest_from_Postgres_to_Snowflake.scheduled__2025-07-20T03_10_00+00_00</h3>
            <div class="meta-data">
                <strong>Severity:</strong> HIGH | 
                <strong>File:</strong> attempt=2.log | 
                <strong>Execution:</strong> task_id=load_contest_winners_operator
            </div>
            
            <div class="section-title">Error Details:</div>
            <pre>Line 1: [2025-07-21T03:15:40.903+0000] {{taskinstance.py:1824}} ERROR - Task failed with exception</pre>
            
            <div class="section-title">Context Lines:</div>
            <pre>[2025-07-21T03:15:40.903+0000] {{taskinstance.py:1824}} ERROR - Task failed with exception
Traceback (most recent call last):
  File &quot;/usr/local/airflow/.local/lib/python3.10/site-packages/sqlalchemy/engine/base.py&quot;, line 1910, in _execute_context</pre>
            
            <div class="section-title">AI Analysis & Suggestions:</div>
            <pre>**Root Cause:** Failed to establish a connection with Snowflake database, likely due to incorrect credentials or network issues.

**Recommended Solution:**
  - Verify Snowflake database credentials and ensure they match the Airflow DAG settings.
  - Check network connectivity and firewall rules to allow access from Airflow&#x27;s host machine.
  - Update Airflow DAG settings to use a valid Snowflake connection string.

**Prevention Tips:**
  - Regularly review and update database credentials in Airflow DAG settings.
  - Implement network monitoring and alerting to detect potential connectivity issues.
  - Use environment variables or secure storage to manage sensitive database credentials.</pre>
            
            
        </div>
        
        <div class="error-card severity-HIGH">
            <h3>ðŸš¨ Database Connection in Challenge_contest_from_Postgres_to_Snowflake.scheduled__2025-07-20T03_10_00+00_00</h3>
            <div class="meta-data">
                <strong>Severity:</strong> HIGH | 
                <strong>File:</strong> attempt=1.log | 
                <strong>Execution:</strong> task_id=load_contest_winners_operator
            </div>
            
            <div class="section-title">Error Details:</div>
            <pre>Line 1: [2025-07-21T03:10:36.534+0000] {{taskinstance.py:1824}} ERROR - Task failed with exception</pre>
            
            <div class="section-title">Context Lines:</div>
            <pre>[2025-07-21T03:10:36.534+0000] {{taskinstance.py:1824}} ERROR - Task failed with exception
Traceback (most recent call last):
  File &quot;/usr/local/airflow/.local/lib/python3.10/site-packages/sqlalchemy/engine/base.py&quot;, line 1910, in _execute_context</pre>
            
            <div class="section-title">AI Analysis & Suggestions:</div>
            <pre>**Root Cause:** Failed to establish a connection with Snowflake database due to incorrect credentials.

**Recommended Solution:**
  - Check the Airflow connection ID for Challenge_contest_from_Postgres_to_Snowflake and verify that the Snowflake credentials are correct.
  - Update the Snowflake connection details in the Airflow UI or through the `airflow config` command.
  - Verify that the Snowflake database and user credentials match the expected values.

**Prevention Tips:**
  - Regularly review and update Airflow connections to ensure they remain accurate and secure.
  - Use environment variables or a secrets manager to store sensitive credentials, such as Snowflake passwords.
  - Implement connection validation checks before executing tasks that rely on database connections.</pre>
            
            
        </div>
        
        <div class="error-card severity-MEDIUM">
            <h3>ðŸš¨ Database Connection in Challenge_contest_from_Postgres_to_Snowflake.scheduled__2025-07-20T03_10_00+00_00</h3>
            <div class="meta-data">
                <strong>Severity:</strong> MEDIUM | 
                <strong>File:</strong> attempt=2.log | 
                <strong>Execution:</strong> task_id=load_contest_winners_operator
            </div>
            
            <div class="section-title">Error Details:</div>
            <pre>Line 1: [2025-07-21T03:15:40.947+0000] {{standard_task_runner.py:104}} ERROR - Failed to execute job 445842 for task load_contest_winners_operator ((psycopg2.errors.UndefinedTable) relation &quot;contest_winners&quot; does not exist</pre>
            
            <div class="section-title">Context Lines:</div>
            <pre>[2025-07-21T03:15:40.947+0000] {{standard_task_runner.py:104}} ERROR - Failed to execute job 445842 for task load_contest_winners_operator ((psycopg2.errors.UndefinedTable) relation &quot;contest_winners&quot; does not exist
LINE 2:         from contest_winners
                     ^</pre>
            
            <div class="section-title">AI Analysis & Suggestions:</div>
            <pre>**Root Cause:** The &#x27;contest_winners&#x27; table does not exist in the PostgreSQL database, causing a failure in the load_contest_winners_operator task.

**Recommended Solution:**
  - Check the PostgreSQL database schema to ensure the &#x27;contest_winners&#x27; table exists and is correctly spelled.
  - Verify that the table was created with the correct name and structure before running the DAG.
  - Update the Airflow DAG to use the correct table name or create a new task to recreate the table if necessary.

**Prevention Tips:**
  - Regularly review database schema changes to ensure tables are up-to-date with the DAG&#x27;s dependencies.
  - Use Airflow&#x27;s built-in support for dynamic table names or parameterized queries to avoid hardcoding table names.
  - Implement automated testing of database connections and table existence before running DAGs.</pre>
            
            
        </div>
        
        <div class="error-card severity-MEDIUM">
            <h3>ðŸš¨ Database Connection in Challenge_contest_from_Postgres_to_Snowflake.scheduled__2025-07-20T03_10_00+00_00</h3>
            <div class="meta-data">
                <strong>Severity:</strong> MEDIUM | 
                <strong>File:</strong> attempt=3.log | 
                <strong>Execution:</strong> task_id=load_contest_winners_operator
            </div>
            
            <div class="section-title">Error Details:</div>
            <pre>Line 1: [2025-07-21T03:20:50.265+0000] {{standard_task_runner.py:104}} ERROR - Failed to execute job 445850 for task load_contest_winners_operator ((psycopg2.errors.UndefinedTable) relation &quot;contest_winners&quot; does not exist</pre>
            
            <div class="section-title">Context Lines:</div>
            <pre>[2025-07-21T03:20:50.265+0000] {{standard_task_runner.py:104}} ERROR - Failed to execute job 445850 for task load_contest_winners_operator ((psycopg2.errors.UndefinedTable) relation &quot;contest_winners&quot; does not exist
LINE 2:         from contest_winners
                     ^</pre>
            
            <div class="section-title">AI Analysis & Suggestions:</div>
            <pre>**Root Cause:** The &#x27;contest_winners&#x27; table does not exist in the PostgreSQL database, causing a failure in the load_contest_winners_operator task.

**Recommended Solution:**
  - Check the PostgreSQL database schema to ensure the &#x27;contest_winners&#x27; table exists and is correctly spelled.
  - Verify that the table was created with the correct name and structure before running the DAG.
  - Update the Airflow DAG to use the correct table name or create a new task to recreate the missing table.

**Prevention Tips:**
  - Regularly review database schema changes to ensure data consistency across tasks.
  - Use Airflow&#x27;s built-in support for dynamic table names or create custom operators to handle schema changes.
  - Implement automated testing for DAGs to catch schema-related errors before execution.</pre>
            
            
        </div>
        </body></html>